<sdf version='1.11'>
  <model name='pinchy'>
    <link name='root'>
      <inertial>
        <pose>0 0 2.4975024975024978e-05 0 0 0</pose>
        <mass>1001</mass>
        <inertia>
          <ixx>0.0033243756243756251</ixx>
          <ixy>0</ixy>
          <ixz>0</ixz>
          <iyy>0.0033243756243756251</iyy>
          <iyz>0</iyz>
          <izz>0.0050000000000000001</izz>
        </inertia>
      </inertial>
      <collision name='root_fixed_joint_lump__massive_block_collision_collision'>
        <pose>0 0 0 0 0 0</pose>
        <geometry>
          <box>
            <size>0.10000000000000001 0.10000000000000001 0.0001</size>
          </box>
        </geometry>
      </collision>
      <collision name='root_fixed_joint_lump__base_link_collision_1'>
        <pose>0 0 0.025000000000000001 0 0 0</pose>
        <geometry>
          <cylinder>
            <length>0.050000000000000003</length>
            <radius>0.10000000000000001</radius>
          </cylinder>
        </geometry>
      </collision>
      <visual name='root_fixed_joint_lump__massive_block_visual_visual'>
        <pose>0 0 0 0 0 0</pose>
        <geometry>
          <box>
            <size>0.10000000000000001 0.10000000000000001 0.0001</size>
          </box>
        </geometry>
        <material>
          <diffuse>0 0 0 0</diffuse>
          <ambient>0 0 0 0</ambient>
        </material>
      </visual>
      <visual name='root_fixed_joint_lump__base_link_visual_1'>
        <pose>0 0 0.025000000000000001 0 0 0</pose>
        <geometry>
          <cylinder>
            <length>0.050000000000000003</length>
            <radius>0.10000000000000001</radius>
          </cylinder>
        </geometry>
        <material>
          <diffuse>0.9375 0.9375 0.9375 1</diffuse>
          <ambient>0.9375 0.9375 0.9375 1</ambient>
        </material>
      </visual>
    </link>
    <joint name='base_link_to_torso' type='revolute'>
      <pose relative_to='root'>0 0 0.050000000000000003 0 0 0</pose>
      <parent>root</parent>
      <child>torso</child>
      <axis>
        <xyz>0 0 1</xyz>
        <limit>
          <lower>-inf</lower>
          <upper>inf</upper>
        </limit>
        <dynamics>
          <spring_reference>0</spring_reference>
          <spring_stiffness>0</spring_stiffness>
        </dynamics>
      </axis>
    </joint>
    <link name='torso'>
      <pose relative_to='base_link_to_torso'>0 0 0 0 0 0</pose>
      <inertial>
        <pose>0 0 0.25 0 0 0</pose>
        <mass>1</mass>
        <inertia>
          <ixx>0.0021459999999999999</ixx>
          <ixy>0</ixy>
          <ixz>0</ixz>
          <iyy>0.0021459999999999999</iyy>
          <iyz>0</iyz>
          <izz>0.00125</izz>
        </inertia>
      </inertial>
      <collision name='torso_collision'>
        <pose>0 0 0.25 0 0 0</pose>
        <geometry>
          <cylinder>
            <length>0.5</length>
            <radius>0.050000000000000003</radius>
          </cylinder>
        </geometry>
      </collision>
      <visual name='torso_visual'>
        <pose>0 0 0.25 0 0 0</pose>
        <geometry>
          <cylinder>
            <length>0.5</length>
            <radius>0.050000000000000003</radius>
          </cylinder>
        </geometry>
        <material>
          <diffuse>0.9375 0.9375 0.9375 1</diffuse>
          <ambient>0.9375 0.9375 0.9375 1</ambient>
        </material>
      </visual>
    </link>
    <joint name='torso_to_upper_arm' type='revolute'>
      <pose relative_to='torso'>0 -0.10000000000000001 0.45000000000000001 3.1415926535897931 1.5707926536359933 3.1415926535897931</pose>
      <parent>torso</parent>
      <child>upper_arm</child>
      <axis>
        <xyz>0 1 0</xyz>
        <limit>
          <lower>-inf</lower>
          <upper>inf</upper>
        </limit>
        <dynamics>
          <spring_reference>0</spring_reference>
          <spring_stiffness>0</spring_stiffness>
        </dynamics>
      </axis>
    </joint>
    <link name='upper_arm'>
      <pose relative_to='torso_to_upper_arm'>0 0 0 0 0 0</pose>
      <inertial>
        <pose>0 0 0.20000000000000001 0 0 0</pose>
        <mass>1</mass>
        <inertia>
          <ixx>0.01396</ixx>
          <ixy>0</ixy>
          <ixz>0</ixz>
          <iyy>0.01396</iyy>
          <iyz>0</iyz>
          <izz>0.00125</izz>
        </inertia>
      </inertial>
      <collision name='upper_arm_collision'>
        <pose>0 0 0.20000000000000001 0 0 0</pose>
        <geometry>
          <cylinder>
            <length>0.40000000000000002</length>
            <radius>0.050000000000000003</radius>
          </cylinder>
        </geometry>
      </collision>
      <visual name='upper_arm_visual'>
        <pose>0 0 0.20000000000000001 0 0 0</pose>
        <geometry>
          <cylinder>
            <length>0.40000000000000002</length>
            <radius>0.050000000000000003</radius>
          </cylinder>
        </geometry>
        <material>
          <diffuse>0.9375 0.9375 0.9375 1</diffuse>
          <ambient>0.9375 0.9375 0.9375 1</ambient>
        </material>
      </visual>
    </link>
    <joint name='upper_arm_to_lower_arm' type='revolute'>
      <pose relative_to='upper_arm'>0 0.10000000000000001 0.34999999999999998 0 0 0</pose>
      <parent>upper_arm</parent>
      <child>lower_arm</child>
      <axis>
        <xyz>0 1 0</xyz>
        <limit>
          <lower>-inf</lower>
          <upper>inf</upper>
        </limit>
        <dynamics>
          <spring_reference>0</spring_reference>
          <spring_stiffness>0</spring_stiffness>
        </dynamics>
      </axis>
    </joint>
    <link name='lower_arm'>
      <pose relative_to='upper_arm_to_lower_arm'>0 0 0 0 0 0</pose>
      <inertial>
        <pose>0 0 0.20000000000000001 0 0 0</pose>
        <mass>1</mass>
        <inertia>
          <ixx>0.01396</ixx>
          <ixy>0</ixy>
          <ixz>0</ixz>
          <iyy>0.01396</iyy>
          <iyz>0</iyz>
          <izz>0.00125</izz>
        </inertia>
      </inertial>
      <collision name='lower_arm_collision'>
        <pose>0 0 0.20000000000000001 0 0 0</pose>
        <geometry>
          <cylinder>
            <length>0.40000000000000002</length>
            <radius>0.050000000000000003</radius>
          </cylinder>
        </geometry>
      </collision>
      <visual name='lower_arm_visual'>
        <pose>0 0 0.20000000000000001 0 0 0</pose>
        <geometry>
          <cylinder>
            <length>0.40000000000000002</length>
            <radius>0.050000000000000003</radius>
          </cylinder>
        </geometry>
        <material>
          <diffuse>0.9375 0.9375 0.9375 1</diffuse>
          <ambient>0.9375 0.9375 0.9375 1</ambient>
        </material>
      </visual>
    </link>
    <joint name='lower_arm_to_hand' type='revolute'>
      <pose relative_to='lower_arm'>0 0 0.42499999999999999 0 0 0</pose>
      <parent>lower_arm</parent>
      <child>hand</child>
      <axis>
        <xyz>0 1 0</xyz>
        <limit>
          <lower>-inf</lower>
          <upper>inf</upper>
        </limit>
        <dynamics>
          <spring_reference>0</spring_reference>
          <spring_stiffness>0</spring_stiffness>
        </dynamics>
      </axis>
    </joint>
    <link name='hand'>
      <pose relative_to='lower_arm_to_hand'>0 0 0 0 0 0</pose>
      <inertial>
        <pose>0 0 0 0 0 0</pose>
        <mass>1</mass>
        <inertia>
          <ixx>0.00042000000000000002</ixx>
          <ixy>0</ixy>
          <ixz>0</ixz>
          <iyy>0.00042000000000000002</iyy>
          <iyz>0</iyz>
          <izz>0.00042000000000000002</izz>
        </inertia>
      </inertial>
      <collision name='hand_collision'>
        <pose>0 0 0 0 0 0</pose>
        <geometry>
          <box>
            <size>0.050000000000000003 0.050000000000000003 0.050000000000000003</size>
          </box>
        </geometry>
      </collision>
      <visual name='hand_visual'>
        <pose>0 0 0 0 0 0</pose>
        <geometry>
          <box>
            <size>0.050000000000000003 0.050000000000000003 0.050000000000000003</size>
          </box>
        </geometry>
        <material>
          <diffuse>0.9375 0.9375 0.9375 1</diffuse>
          <ambient>0.9375 0.9375 0.9375 1</ambient>
        </material>
      </visual>
    </link>
    <frame name='massive_block_to_base_link' attached_to='massive_block'>
      <pose>0 0 0 0 0 0</pose>
    </frame>
    <frame name='base_link' attached_to='massive_block_to_base_link'>
      <pose>0 0 0 0 0 0</pose>
    </frame>
    <frame name='root_to_massive_block' attached_to='root'>
      <pose>0 0 0 0 0 0</pose>
    </frame>
    <frame name='massive_block' attached_to='root_to_massive_block'>
      <pose>0 0 0 0 0 0</pose>
    </frame>
  </model>
</sdf>
